Workbook

Sheet Исходные данные
A1: Исходные данные камерной сушильной печи
A4: Исходные данные | B4: Значение | C4: Ед. измерения | D4: Обозначения
A5: Масса сухого материала | B5: 10000 | C5: кг | D5: G с.м
A6: Начальная влажность форм | B6: 8 | C6: % | D6: W1нач | G6: Изменение температур газовой среды в процессе сушки
A7: Конечная влажность форм | B7: 2 | C7: % | D7: W2кон | H7: t нач | I7: t | J7: tкон
A8: Начальная температура материала | B8: 0 | C8: ˚С | D8: t м.нач | G8: 0 | H8: 550 | I8: 800 | J8: 650
A9: Коэффициент расхода воздуха | B9: 1.15 | D9: α | G9: 1 | H9: 200 | I9: 400 | J9: 400
A10: Масса выносной топки и тележки | B10: 2000 | C10: кг | D10: Мтелеги+топок | G10: 2 | H10: 100 | I10: 330 | J10: 350
A11: Температура воздуха | B11: 20 | C11: ˚С | D11: tвозд
A12: Температура рециркулята в конце сушки | B12: 230 | C12: ˚С | D12: tрец
A13: Увеличение коэффициента расхода воздуха(рециркуляция) | B13: 0.3 | D13: Δα
A14: Толщина кирпича | B14: 0.12 | C14: м | D14: Sкирпича
A15: Толщина двери | B15: 0.04 | C15: м | D15: Sдвери
A16: Толщина засыпки | B16: 0.08 | C16: м | D16: Sзасыпки
A17: Время сушки | B17: 28800 | C17: с | D17: τсушки
A18: Время подъёма температуры | B18: 14400 | C18: с
A19: Время выдержки | B19: 14400 | C19: с | D19: τвыдержки
A20: Время охлаждения | B20: 25200 | C20: с | D20: τохлаждения
A21: Площадь внутренней поверхности двери | B21: 9.25 | C21: м2 | D21: Fдвери
A22: Диаметр отверстия выходного сечения топок | B22: 0.095 | C22: м | D22: D
A23: Площадь поперечного сечения топки | B23: 0.432 | C23: м2 | D23: Fсеч
A24: Площадь внутренней поверхности стен сушильной камеры | B24: 39.5 | C24: м2 | D24: Fвнутр
A25: Площадь внешней поверхности стен сушильной камеры | B25: 46 | C25: м2 | D25: Fвнешн
A26: Площадь средней поверхности стен сушильной камеры | B26: 42.8 | C26: м2 | D26: Fсред
A27: Площадь свода | B27: 28.9 | C27: м2 | D27: Fсвода
A28: Высота верха садки над уровнем пола | B28: 2 | C28: м | D28: L

Sheet Расчет горения топлива
A1: Режимы и расчёт горения топлива камерной и сушильной печи
A2: Аэродинамический и температурный режимы | E2: К | F2: =-0.001*(0.5*('Исходные данные'!I8+'Исходные данные'!I9))+1.3 -> 0.7 | H2: Расчет количества кислорода и воздуха для сжигания 1м3 газа
A3: Величины,найденные путем расчета | B3: Значения | C3: Ед.Измерения | D3: Обозначение | I3: Vo2 | J3: =0.01*(2*C12+3.5*C13+5*C14+6.5*C15+8*C16) -> 2.0738793 | K3: м3/м3
A4: Относительный расход | B4: =1+0.5*(0.155*2/('Исходные данные'!B22/2)-1) -> 3.7631579 | D4: Z | I4: Lo | J4: =4.76*J3 -> 9.8716654 | K4: м3/м3
A5: Теплосодержание газов(Энтальпия), выходящих из топки в рабочее пространство | B5: =(513+B4*((6.7851*('Расчет горения топлива'!J9^0.6906))-(6.7851*('Расчет горения топлива'!J10^0.6906))))/F2 -> 711.45405 | C5: кДж/м3 | D5: i0 | I5: Lα | J5: =B22*J4 -> 11.352415 | K5: м3/м3
A6: Температура газов,выходящих из топки | B6: =B5/1.4 -> 508.18146 | C6: ˚С | D6: t0
A7: Теплосодержание топочных газов | B7: ='Расчет горения топлива'!B27*0.9 -> 2969.4806 | C7: кДж/м3 | D7: Iф | H7: Расчет объема и состава продуктов сгорания при сжигании 1м3 газа
A8: Количество воздуха,необходимое для снижения энтальпии продуктов сгорания | B8: =(B7-B5)/(B5-25) -> 3.2894068 | C8: м3/м3 | D8: Хв | J8: При α=1 | N8: При α=1,15
I9: VoCO2 | J9: =0.01*(C17+C12+2*C13+3*C14+4*C15+5*C16) -> 1.067409 | K9: м3/м3 | M9: VαCO2 | N9: =J9 -> 1.067409 | O9: м3/м3
I10: VoH2O | J10: =0.01*(C19+2*C12+3*C13+4*C14+5*C15+6*C16) -> 2.033991 | K10: м3/м3 | M10: VαH2O | N10: =J10+(B22-1)*0.00124*B21*J4 -> 2.0596968 | O10: м3/м3
A11: Расчет горения топлива | B11: сухой газ | C11: влажный газ | D11: Ед.Измерения | I11: VoN2 | J11: =0.01*C18+3.76*J3 -> 7.8272726 | K11: м3/м3 | M11: VαN2 | N11: =0.01*C18+B22*3.76*J3 -> 8.9969405 | O11: м3/м3
A12: CH4 | B12: 90 | C12: =B12*((100-C19)/100) -> 88.459306 | D12: % | I12: Vo | J12: =SUM(J9:J11) -> 10.928673 | K12: м3/м3 | M12: VО2изб | N12: =(B22-1)*J3 -> 0.31108189 | O12: м3/м3
A13: C2H6 | B13: 4.5 | C13: =B13*((100-C19)/100) -> 4.4229653 | D13: % | M13: Vα | N13: =SUM(N9:N12) -> 12.435128 | O13: м3/м3
A14: C3H8 | B14: 0.9 | C14: =B14*((100-C19)/100) -> 0.88459306 | D14: %
A15: C4H10 | B15: 0.3 | C15: =B15*((100-C19)/100) -> 0.29486435 | D15: % | I15: Состав при α=1 | M15: Состав при α =1,15
A16: C5H12 | B16: 1.1 | C16: =B16*((100-C19)/100) -> 1.0811693 | D16: % | I16: VoСO2 | J16: =J9*100/J12 -> 9.7670505 | M16: VαCO2 | N16: =N9*100/N13 -> 8.5838195
A17: CO2 | B17: 0.2 | C17: =B17*((100-C19)/100) -> 0.19657624 | D17: % | I17: VoH2O | J17: =J10*100/J12 -> 18.61151 | M17: VαH2O | N17: =N10*100/N13 -> 16.563535
A18: N2 | B18: 3 | C18: =B18*((100-C19)/100) -> 2.9486435 | D18: % | I18: VoN2 | J18: =J11*100/J12 -> 71.621439 | M18: VαN2 | N18: =N11*100/N13 -> 72.351007
A19: H2O | C19: =(0.1244*14)/(1+0.00124*14) -> 1.7118817 | D19: % | M19: VО2изб | N19: =N12*100/N13 -> 2.501638
A20: Сумма всех компонентов | B20: =SUM(B12:B18) -> 100 | C20: =SUM(C12:C19) -> 100 | D20: %
A21: Влагосодержание воздуха | B21: 14
A22: α | B22: 1.15
A24: Расчёт теплоты сгорания и температур горения | B24: Значения | C24: Ед. Измерения | G24: 0,5*(to+t1) | H24: К
A25: Q низшее рабочее | B25: =358*C12+636*C13+913*C14+1185*C15+1465*C16 -> 37222.398 | C25: кДж/м3 | G25: 400 | H25: 0.9
A26: iтопл общ | B26: =(B25/N13)+((1.57*20)/N13)+((1.327*300*J5)/N13) -> 3359.2894 | C26: кДж/м3 | G26: 500 | H26: 0.8
A27: iб общ | B27: =B26-((0.02*B25)/N13) -> 3299.4229 | C27: кДж/м3 | G27: 600 | H27: 0.7
A28: Ų избыточного воздуха | B28: =((J5-J4)/N13)*100 -> 11.907797 | C28: % | G28: 700 | H28: 0.6
A29: tтά газов | B29: =6.7851*(B26)^0.6906 -> 1848.3437 | C29: ˚С | G29: 800 | H29: 0.5
A30: tбά газов | B30: =6.7851*(B27)^0.6906 -> 1825.5323 | C30: ˚С
G36: температура | H36: 200 | I36: 400 | J36: 600 | K36: 800 | L36: 1000 | M36: 1400 | N36: 1600 | O36: 1800 | P36: 2000 | Q36: 2200 | R36: 2400
G37: энтальпия | H37: 100 | I37: 500 | J37: 800 | K37: 1100 | L37: 1400 | M37: 2300 | N37: 2700 | O37: 3000 | P37: 3500 | Q37: 3900 | R37: 4500

Sheet Тепловой баланс
A1: Тепловой баланс камерной сушильной печи
B2: Без рециркуляции | J2: С рециркуляцией
A3: Расход теплоты на нагревание и удаление влаги | I3: Содержание в газах избыточн. воздуха | J3: =('Исходные данные'!B9+'Исходные данные'!B13-1)*'Расчет горения топлива'!J4*100/('Расчет горения топлива'!J5+'Исходные данные'!B13*'Расчет горения топлива'!J4) -> 31.034483 | K3: % | L3: Vlp
A4: toсредн | B4: =(('Исходные данные'!H8+('Исходные данные'!I8-'Исходные данные'!H8)/0.8)*'Исходные данные'!B18/('Исходные данные'!B18+'Исходные данные'!B19))+0.5*('Исходные данные'!I8+'Исходные данные'!J8)*'Исходные данные'!B19/('Исходные данные'!B19+'Исходные данные'!B18) -> 793.75 | C4: °С | D4: t.o.ср | I4: Количество рециркулята | J4: =('Расчет горения топлива'!B7-'Расчет горения топлива'!B5)/('Расчет горения топлива'!B5-('Исходные данные'!B12/6.7851)^(1/0.6906)) -> 4.1270732 | K4: м3/м3 | L4: Хр
A5: t1средн | B5: =(('Исходные данные'!H9+('Исходные данные'!I9-'Исходные данные'!H9)/0.8)*'Исходные данные'!B18/('Исходные данные'!B18+'Исходные данные'!B19))+0.5*('Исходные данные'!I9+'Исходные данные'!J9)*'Исходные данные'!B19/('Исходные данные'!B19+'Исходные данные'!B18) -> 425 | C5: °С | D5: t.1.ср | I5: Физич. теплота, уносимая отход.газами | J5: =(B16+'Расчет горения топлива'!B8*(('Исходные данные'!J10/6.7851)^(1/0.6906)-(('Исходные данные'!B12/6.7851)^(1/0.6906))))*'Расчет горения топлива'!J5 -> 8560.5789 | K5: кДж | L5: q2’ о.г
A6: средн t от toсредн и t1средн | B6: =0.5*(B4+B5) -> 609.375 | C6: °С | D6: t.ср(t.1+t.2)ср | I6: Потери теплоты с отходящими газами | J6: =J5*'Исходные данные'!B17 -> 2.4654467e+08 | K6: кДж | L6: Q2
A7: t2средн | B7: =('Исходные данные'!H10+('Исходные данные'!I10-100)/(0.7+1))*('Исходные данные'!B18/'Исходные данные'!B17)+0.5*('Исходные данные'!I10+'Исходные данные'!J10)*'Исходные данные'!B18/'Исходные данные'!B17 -> 287.64706 | C7: °С | D7: t.2.ср | I7: Tеплота топлива | J7: =B59*J8 -> 32876397 | K7: кДж | L7: Qxh’1
A8: Влажность нач на сухую массу | B8: ='Исходные данные'!B6/(1-0.01*'Исходные данные'!B6) -> 8.6956522 | C8: % | D8: W c.м нач | I8: Расход топлива | J8: =(B11+B36+B55)/(B59-B18-B21-B39) -> 0.030668129 | K8: м3/с | L8: В’1
A9: Влажность кон на сухую массу | B9: ='Исходные данные'!B7/(1-0.01*'Исходные данные'!B7) -> 2.0408163 | C9: % | D9: W c.м кон | I9: Расход теплоты на нагрев | J9: =B11 -> 4530545 | K9: кДж | L9: Q1’
A10: Температура массы сух.материала | B10: =0.5*('Исходные данные'!J9+'Исходные данные'!J10)-100 -> 275 | C10: °С | D10: t м.кон | I10: Потери теплоты с отходящими газами | J10: =J8*B18 -> 8267902 | K10: кДж | L10: Q2’
A11: Расход теплоты на нагрев | B11: =((0.84+0.01*B9*4.19)*(B10-'Исходные данные'!B8)+0.01*(B8-B9)*(2675-83.8+2.09*('Тепловой баланс'!B7-100)))*'Исходные данные'!B5 -> 4530545 | C11: кДж | D11: Q1 | I11: Потери теплоты вследствие хим. недожога | J11: =J8*B21 -> 657527.79 | K11: кДж | L11: Q3’
I12: Потери теплоты топкой | J12: =J8*B39 -> 6575277.9 | K12: кДж | L12: Q5 топ’
I13: Затраты на нагрев приспособлений и на покрытие | J13: =B36 -> 10937972 | K13: кДж | L13: Q5 р.п’
A14: Потери теплоты с отходящими газами | I14: Аккумулированное тепло стенками раб. простр-ва | J14: =B55 -> 1907171.8 | K14: кДж | L14: Q6’
A15: Удельное значение теплоты отходящих газов | B15: =(B17+1.3*(B16-25))*'Расчет горения топлива'!N13 -> 9360.8559 | C15: кДж | D15: q2 | I15: Сумма Q | J15: =SUM(J9,J10,J11,J12,J13,J14) -> 32876397 | K15: кДж | L15: ∑ Q’
A16: Энтальпия отходящих газов | B16: =('Исходные данные'!J10/6.7851)^(1/0.6906) -> 301.8178 | C16: кДж/м3 | D16: i2 о.г | I16: КПД | J16: =J9/J15 -> 0.1378054 | L16: η’
A17: Энтальпия воздуха | B17: =1.0286*(B7^1.0501) -> 392.91204 | C17: кДж/м3 | D17: i2 в | I17: Расход теплоты на 1 кг испаренной влаги | J17: =J15/B62 -> 49402.265 | K17: кДж/кг | L17: qисп’
A18: Потеря теплоты с отходящими газами | B18: =B15*'Исходные данные'!B17 -> 2.6959265e+08 | C18: кДж | D18: Q2
A20: Потери теплоты вследствие хим. недожога
A21: Потери теплоты вследствие хим. недожога | B21: =0.02*'Расчет горения топлива'!B25*'Исходные данные'!B17 -> 21440101 | C21: кДж | D21: Q3
A23: Потери теплоты на нагрев приспособлений стенок
A24: Затраты на нагрев приспособлений | B24: =0.515*(B10-'Исходные данные'!B11)*'Исходные данные'!B10 -> 262650 | C24: кДж | D24: Q5п.р
A25: Температура наружной поверхности стенок | B25: =8.33*(-(8-0.06*'Исходные данные'!B11)+SQRT(((8-0.06*'Исходные данные'!B11)^2)+0.24*(700+8*'Исходные данные'!B11))) -> 75.758461 | C25: ˚С | D25: t2'
A26: Коффициент теплопроводности | B26: =0.41+0.00035*((B6+B25)/2) -> 0.52989836 | C26: Вт/(м*К) | D26: λ
A27: Толщина стенок | B27: =B26*(B6-B25)/(0.8*700) -> 0.50493308 | C27: м | D27: S
A28: Потери теплоты теплопроводностью через стенки | B28: =0.01*B26*(B6-B25)*0.5*('Исходные данные'!B24+'Исходные данные'!B25)*'Исходные данные'!B17/'Тепловой баланс'!B27 -> 6894720 | C28: кДж | D28: Q5т.ст
A29: λ кирпича | B29: =0.508+0.00035*0.5*(B5+295) -> 0.634 | C29: Вт/(м*К) | D29: λк | I29: Тепловой баланс (без рециркуляции)
A30: λ засыпка | B30: =0.077+0.000279*0.5*(B25+295) -> 0.12872081 | C30: Вт/(м*К) | D30: λз | J30: кДж | K30: %
A31: λ/S свод | B31: =1/('Исходные данные'!B14/'Тепловой баланс'!B29+'Исходные данные'!B16/'Тепловой баланс'!B30) -> 1.2333884 | C31: Вт/(м^2*К) | D31: λ/Sсв | I31: Q1 | J31: =B11 -> 4530545 | K31: =(J31/$J$37)*$K$37 -> 13.78054
A32: λ/S двери | B32: =0.0084/'Исходные данные'!B15 -> 0.21 | C32: Вт/(м^2*К) | D32: λ/Sдв | I32: Q2 | J32: =B18*B58 -> 8267902 | K32: =(J32/$J$37)*$K$37 -> 25.148444
A33: Потери через свод | B33: =0.01*B31*(B5-B25)*'Исходные данные'!B27*'Исходные данные'!B17 -> 3585222.3 | C33: кДж | D33: Q5т.св | I33: Q3 | J33: =B21*B58 -> 657527.79 | K33: =(J33/$J$37)*$K$37 -> 1.9999996
A34: Потери через двери | B34: =0.01*B32*(B5-B25)*'Исходные данные'!B21*'Исходные данные'!B17 -> 195379.69 | C34: кДж | D34: Q5т.дв | I34: Q5 топкой | J34: =B39*B58 -> 6575277.9 | K34: =(J34/$J$37)*$K$37 -> 19.999996
A35: Общие потери тепла теплопроводностью | B35: =B28+B33+B34 -> 10675322 | C35: кДж | D35: Q5т.р.п | I35: Q5 р.п | J35: =B36 -> 10937972 | K35: =(J35/$J$37)*$K$37 -> 33.269984
A36: Затраты на нагрев приспособлений и на покрытие | B36: =B24+B35 -> 10937972 | C36: кДж | D36: Q 5 р.п | I36: Q6 | J36: =B55 -> 1907171.8 | K36: =(J36/$J$37)*$K$37 -> 5.8010365
I37: Сумма Q | J37: =SUM(J31,J32,J33,J34,J35,J36) -> 32876397 | K37: 100
A38: Потери теплоты топкой
A39: Потери теплоты топкой | B39: =(1-0.8)*'Расчет горения топлива'!B25*'Исходные данные'!B17 -> 2.1440101e+08 | C39: кДж | D39: Q5топ
A41: Средняя температура стенок начальная | B41: =0.5*(0.5*('Исходные данные'!B11+'Исходные данные'!H8)+'Исходные данные'!H9) -> 242.5 | C41: ˚С | D41: t ср. нач
A42: Средняя температура стенок за 1 период | B42: =0.5*('Исходные данные'!I8+'Исходные данные'!I9) -> 600 | C42: ˚С | D42: t ср. 1пер
A43: Средняя температура стенок за 2 период | B43: =0.5*('Исходные данные'!J8+'Исходные данные'!J9) -> 525 | C43: ˚С | D43: t ср. 2пер
...
